Workbook

Sheet Active Orders
A1: SL No. | B1: KI ID | C1: Order Received | D1: Region | E1: City | F1: Circuit ID | G1: Order Number | H1: Customer Name | I1: Customer Contact | J1: BW | K1: LOS Performed | L1: LOS Status | M1: LOS ID | N1: CWO Date | O1: Installation Start Date | P1: Installation Complete Date | Q1: Delivery Date | R1: Pole | S1: Invoice | T1: Order Status | U1: Assigned To
A2: 1 | B2: KIC-001-MW-MEL-STC | C2: 46205 | D2: CENTRAL | E2: QASSIM | F2: QASSIM-RIYADH DIAS11003 | G2: I-14977452579171 | H2: Fosam Limited Company | I2: ابتسام اليامي - 553584472 | J2: 20MBPs | K2: 46208 | L2: CLOS | M2: 601-22-000 | N2: 46216 | O2: 46231 | P2: 46232 | Q2: 46232 | S2: Issued | T2: Delivered | U2: Haroon
A3: 2 | B3: KIC-002-MW-MEL-STC | C3: 46205 | D3: CENTRAL | E3: RIYADHDST | F3: RIYADHDST-RIYADH DIAS11019 | G3: I14977108106221 | H3: Bunyan for Industry CompanySole Partnership | I3: وليد الغامدي - 565577234 | J3: 25MBPs | K3: 46208 | L3: CLOS | M3: ZAKA160 | N3: 46216 | O3: 46226 | P3: 46228 | Q3: 46228 | S3: Issued | T3: Delivered | U3: Haroon
A4: 3 | B4: KIC-003-MW-MEL-STC | C4: 46211 | D4: CENTRAL | E4: RIYADHDST | F4: RIYADHDST-RIYADH DIAS11048 | G4: I14978406074781 | H4: MINISTRY OF ISLAMIC AFFAIRS1 | I4: mutlatq mutlatq- 554141990 | J4: 6MBPs | K4: 46212 | L4: CLOS | M4: ZTMA001 | N4: 46222 | O4: 46228 | P4: 46229 | Q4: 46229 | S4: Issued | T4: Delivered | U4: Shukoor
A5: 4 | B5: KIC-004-MW-MEL-STC | C5: 46211 | D5: CENTRAL | E5: QASSIM | F5: QASSIM-RIYADH DIAS11007 | G5: I14978403932431 | H5: MINISTRY OF ISLAMIC AFFAIRS1 | I5: mutlatq mutlatq- 554141990/+966561733000فواز الوتيد دوام | J5: 6MBPs | K5: 46216 | L5: CLOS | M5: ZBRA012 | N5: 46230 | O5: 46243 | P5: 46243 | Q5: 46243 | T5: Delivered | U5: Haroon
A6: 5 | B6: KIC-005-MW-MEL-STC | C6: 46213 | D6: CENTRAL | E6: QASSIM | F6: QASSIM-RIYADH W-DIA64771 | G6: I-154546342-0886 | H6: NOURNET ISP 1 | I6: Atif Ahmad - 966504164527 | J6: 8MBPs | K6: 46216 | L6: CLOS | M6: ZBDA012 | N6: 46244 | T6: Installation will be start tomorrow. | U6: Haroon
A7: 6 | B7: KIC-006-MW-MEL-STC | C7: 46234 | D7: CENTRAL | E7: RIYADHDST | F7: RIYADHDISTRICTS-RIYADH W-DIA64993 | G7: I-154915203-2128 | H7: NOURNET ISP 1 | I7: Atif Ahmad - 966504164527 | J7: 4MBPs | K7: 46216 | L7: CLOS | M7: ZDAA055 | N7: 46234 | O7: 46236 | P7: 46236 | Q7: 46206 | S7: Issued | T7: Delivered | U7: Haroon
A8: 7 | B8: KIC-007-MW-MEL-STC | C8: 46215 | D8: CENTRAL | E8: RIYADHDST | F8: RIYADHDISTRICTS-RIYADH W-DIA64472 | G8: I-154001313-9084 | H8: NOURNET ISP 1 | I8: Atif Ahmad - 966504164527 | J8: 8MBPs | K8: 46216 | L8: CLOS | M8: ZTMA001 | T8: Under Activation
A9: 8 | B9: KIC-008-MW-MEL-Mobily | C9: 46224 | D9: CENTRAL | E9: RIYADH | F9: SIP Link 1-274297070922 | G9: 1001274298017324 | H9: Life Care Medical Complex مجمع لايف كير الطبي | I9: 0573240869 منهاز | J9: 1MBPs | K9: 46224 | L9: CLOS | M9: C6406 | N9: 46226 | O9: 46226 | P9: 46226 | Q9: 46237 | R9: Yes | S9: Issued | T9: Delivered | U9: Haroon
A10: 9 | B10: KIC-009-MW-MEL-STC | C10: 46219 | D10: CENTRAL | E10: RIYADHDST | F10: RIYADHDISTRICTS-RIYADH W-DIA65540 | G10: I-155313238-4448 | H10: NOURNET ISP 1 | I10: Atif Ahmad - 966504164527 | J10: 8MBPs | K10: 46223 | L10: CLOS | M10: ZAKA013 | T10: Under Activation
A11: 10 | B11: KIC-010-MW-MEL-STC | C11: 46216 | D11: CENTRAL | E11: RIYADH | F11: RIYADH-RIYADH W-PLL62209 | G11: I-150409923-1673 | H11: TAWAL | I11: Muhanned Abusummah-- 0502897276 | J11: 100Mbps | K11: 46216 | L11: CLOS | M11: ZR4020 | N11: 46219 | O11: 46223 | P11: 46223 | Q11: 46223 | T11: Delivered / CR Pending | U11: Haroon
A12: 11 | B12: KIC-011-MW-MEL-STC | C12: 46216 | D12: CENTRAL | E12: RIYADH | F12: RIYADH-RIYADH W-PLL61594 | G12: I-149425327-9129 | H12: TAWAL | I12: Abdulrahman Balfaqih-- 0502897276 | J12: 100Mbps | K12: 46216 | L12: CLOS | M12: ZAKA953 | N12: 46219 | O12: 46226 | T12: Under MW Installation / Pending Due to Permission Letter | U12: Haroon
A13: 12 | B13: KIC-012-MW-MEL-STC | C13: 46216 | D13: CENTRAL | E13: RIYADHDST | F13: RIYADHDISTRICTS-RIYADH W-PLL61621 | G13: I-149433405-9386 | H13: TAWAL | I13: Abdulrahman Balfaqih-- 0502897276 | J13: 100Mbps | K13: 46216 | L13: CLOS | M13: FRB04 | N13: 46219 | O13: 46220 | P13: 46223 | Q13: 46227 | T13: Delivered / CR Pending | U13: Haroon
A14: 13 | B14: KIC-013-MW-MEL-STC | C14: 46177 | D14: EAST | E14: ALAHSA | F14: ALAHSA-DAMMAM W-PLL60851 | G14: I-148474460-6471 | H14: TAWAL | I14: Muhanned Abusummah-- 0502897276 | J14: 100Mbps | L14: CLOS | M14: FRD12 | T14: Under MW Installation
A15: 14 | B15: KIC-014-MW-MEL-STC | C15: 46222 | D15: CENTRAL | E15: RIYADHDST | F15: RIYADHDISTRICTS-RIYADH W-DIA65578 | G15: I-155424122-6722 | H15: NOURNET ISP 1 | I15: Atif--0504164527 | J15: 8MBPS | K15: 46223 | L15: CLOS | M15: FTR16 | T15: Under Activation
A16: 15 | B16: KIC-015-MW-MEL-STC | C16: 46222 | D16: CENTRAL | E16: RIYADHDST | F16: RIYADHDISTRICTS-RIYADH W-DIA65586 | G16: I-155428046-6760 | H16: NOURNET ISP 1 | I16: Atif--0504164527 | J16: 8MBPS | K16: 46223 | L16: CLOS | M16: FTR14 | N16: 46243 | O16: 46244 | P16: 46245 | T16: Installtion is completed at both ends / pending due to alignment issue | U16: Haroon
A17: 16 | B17: KIC-016-MW-MEL-STC | C17: 46229 | D17: CENTRAL | E17: QASSIM | F17: QASSIM-RIYADH W-DIA66191 | G17: I-155826101-8176 | H17: NOURNET ISP 1 - NOURNET ISP - SC 1 | I17: Atif--0504164527 | J17: 8MBPS | K17: 46231 | L17: CLOS | M17: 689-00-101 | T17: Under Activation
A18: 17 | B18: KIC-017-MW-MEL-STC | C18: 46229 | D18: CENTRAL | E18: HAIL | F18: HAIL-RIYADH W-DIA66171 | G18: I-155792125-7075 | H18: NOURNET ISP 1 - NOURNET ISP - SC 1 | I18: Atif--0504164527 | J18: 8MBPS | K18: 46231 | L18: CLOS | M18: ZHAA035 | T18: Under Activation
A19: 18 | B19: KIC-019-MW-MEL-Mobily | C19: 46232 | D19: CENTRAL | E19: RIYADH | F19: SIP 1-274382463011 | G19: 1001241250916699 | H19: Gulf Training and Education Company-1 شركة الخليج للتدريب والتعليم-1 | I19: MOHAMMED AL-BATATI- 966503282262 | J19: 1MBPs | K19: 46232 | L19: CLOS | M19: C0487 | N19: 46233 | O19: 46233 | P19: 46233 | Q19: 46236 | S19: Issued | T19: Delivered | U19: Haroon
A20: 19 | B20: KIC-020-MW-MEL-STC | C20: 46234 | D20: CENTRAL | E20: RIYADHDST | F20: RIYADHDISTRICTS-RIYADH W-DIA64460 | G20: I-153997754-9021 | H20: NOURNET ISP 1 - NOURNET ISP | I20: Atif Ahmad-0504164527 | J20: 8Mbps | K20: 46231 | L20: CLOS | M20: ZASA009 | N20: 46234 | O20: 46235 | P20: 46236 | Q20: 46236 | S20: Issued | T20: Delivered | U20: Shukoor
A21: 20 | B21: KIC-021-MW-MEL-STC | C21: 46234 | D21: CENTRAL | E21: RIYADHDST | F21: RIYADHDISTRICTS-RIYADH W-DIA64472 | G21: I-154001313-9084 | H21: NOURNET ISP 1 - NOURNET ISP | I21: Atif Ahmad-0504164527 | J21: 8Mbps | K21: 46216 | L21: CLOS | M21: ZTMA001 | N21: 46234 | O21: 46237 | P21: 46238 | Q21: 46239 | T21: Delivered | U21: Shukoor
A22: 21 | B22: KIC-022-MW-MEL-STC | C22: 46234 | D22: CENTRAL | E22: RIYADHDST | F22: RIYADHDISTRICTS-RIYADH W-DIA65540 | G22: I-155312328-4448 | H22: Al Rajhi bank | I22: 0567878430 Yahya | J22: 8Mbps | K22: 46238 | L22: CLOS | M22: ZAK001 Re Routed | N22: 46234 | T22: Re Routed to ZAKA001 due to ZAKA013 tower will be dismental | U22: Shukoor
A23: 22 | B23: KIC-023-MW-MEL-STC | C23: 46237 | D23: CENTRAL | E23: QASSIM | F23: QASSIM-RIYADH W-PLL66095 | G23: I-155754471-6042 | H23: EATC - EATC | I23: Saleh Aljari-- 0553612927 | J23: 10MBPS | M23: SDH 689-11-200-01 | T23: As per customer hold this request he will tell us once site is ready | U23: Haroon
A24: 23 | B24: KIC-024-MW-MEL-Mobily | C24: 46244 | D24: CENTRAL | E24: RIYADh | F24: DIA-Circuit 1-274518091680 | G24: 1001274526958901 | H24: Technology Equipment Trading Company مؤسسة معدات التقانة للتجارة | I24: Mr. Mwafaq - 0568007928 | J24: 4Mbps | K24: 46244 | L24: CLOS | M24: CE1553 | N24: 46245 | O24: 46245 | P24: 46245 | T24: Installation is completed at both ends / will be delivered tomorrow. | U24: Haroon

Sheet Cancelled Orders
A1: SL No. | B1: KI ID | C1: Region | D1: City | E1: Circuit ID | F1: Order Number | G1: Customer Name | H1: Customer Contact | I1: BW | J1: LOS Status | K1: LOS ID | L1: Order Received | M1: LOS Performed | N1: CWO Date | O1: Installation Start Date | P1: Installation Complete Date | Q1: Delivery Date | R1: Order Status | S1: Assigned To
A2: 1 | B2: KIC-018-MW-MEL-STC | C2: CENTRAL | D2: RIYADH | E2: RIYADH-RIYADH W-DIA65391 | F2: I-155156872-9273 | G2: NOURNET ISP 1 | H2: Atif Ahmad - 966504164527 | I2: 8MBPs | J2: CLOS | K2: ZAKA013 | L2: 46219 | M2: 46223 | R2: Cancelled

Sheet Summary
A1: KI ORDERS — SUMMARY DASHBOARD
A3: Live snapshot — all figures below recalculate automatically from the Sheet1 order log
A5: TOTAL ACTIVE ORDERS | C5: LOS COMPLETED (CLOS) | E5: IN PROCESS / INSTALLING | G5: AWAITING TWAL APPROVAL | I5: STATUS NOT YET SET | K5: CANCELLED ORDERS | M5: DELIVERED | O5: GRAND TOTAL (ALL ORDERS)
A6: =COUNTA('Active Orders'!$A$2:$A$499) -> 23 | C6: =COUNTIF('Active Orders'!$L$2:$L$499,"CLOS") -> 22 | E6: =COUNTIF('Active Orders'!$T$2:$T$499,"In Process")+COUNTIF('Active Orders'!$T$2:$T$499,"Under MW Installation")+COUNTIF('Active Orders'!$T$2:$T$499,"Under MW Installation- Brown Condition") -> 1 | G6: =COUNTIF('Active Orders'!$T$2:$T$499,"Under TWAL Approval") -> 0 | I6: =COUNTIFS('Active Orders'!$A$2:$A$499,"<>",'Active Orders'!$T$2:$T$499,"") -> 0 | K6: =COUNTA('Cancelled Orders'!$B$2:$B$500) -> 1 | M6: =COUNTIF('Active Orders'!$T$2:$T$499,"Delivered*") -> 11 | O6: =A6+K6 -> 24
A9: Order Status Breakdown | E9: Region Breakdown
A10: Order Status | B10: Count | C10: Share | E10: Region | F10: Count
A11: Under Activation | B11: =COUNTIF('Active Orders'!$T$2:$T$499,"Under Activation") -> 5 | C11: =B11/$B$16 -> 0.29411765 | E11: CENTRAL | F11: =COUNTIF('Active Orders'!$D$2:$D$499,"CENTRAL") -> 22
A12: Under TWAL Approval | B12: =COUNTIF('Active Orders'!$T$2:$T$499,"Under TWAL Approval") -> 0 | C12: =B12/$B$16 -> 0 | E12: EAST | F12: =COUNTIF('Active Orders'!$D$2:$D$499,"EAST") -> 1
A13: Under MW Installation | B13: =COUNTIF('Active Orders'!$T$2:$T$499,"Under MW Installation") -> 1 | C13: =B13/$B$16 -> 0.058823529 | E13: Not Specified | F13: =COUNTIFS('Active Orders'!$A$2:$A$499,"<>",'Active Orders'!$D$2:$D$499,"") -> 0
A14: Not Yet Set | B14: =COUNTIFS('Active Orders'!$A$2:$A$499,"<>",'Active Orders'!$T$2:$T$499,"") -> 0 | C14: =B14/$B$16 -> 0
A15: Delivered | B15: =COUNTIF('Active Orders'!$T$2:$T$499,"Delivered*") -> 11 | C15: =B15/$B$16 -> 0.64705882 | E15: Cancelled Orders Summary
A16: Total | B16: =SUM(B11:B15) -> 17 | C16: =SUM(C11:C15) -> 1 | E16: Metric | F16: Count
E17: Total Cancelled Orders | F17: =COUNTA('Cancelled Orders'!$B$2:$B$500) -> 1
A20: City Breakdown | E20: LOS Status Breakdown
A21: City | B21: Count | E21: LOS Status | F21: Count
A22: RIYADHDST | B22: =COUNTIF('Active Orders'!$E$2:$E$499,"RIYADHDST") -> 11 | E22: CLOS | F22: =COUNTIF('Active Orders'!$L$2:$L$499,"CLOS") -> 22
A23: QASSIM | B23: =COUNTIF('Active Orders'!$E$2:$E$499,"QASSIM") -> 5 | E23: Pending | F23: =COUNTIF('Active Orders'!$L$2:$L$499,"Pending") -> 0
A24: RIYADH | B24: =COUNTIF('Active Orders'!$E$2:$E$499,"RIYADH") -> 5 | E24: Not Started | F24: =COUNTIFS('Active Orders'!$A$2:$A$499,"<>",'Active Orders'!$L$2:$L$499,"") -> 1
A25: ALAHSA | B25: =COUNTIF('Active Orders'!$E$2:$E$499,"ALAHSA") -> 1
A26: Not Specified | B26: =COUNTIFS('Active Orders'!$A$2:$A$499,"<>",'Active Orders'!$E$2:$E$499,"") -> 0
A29: Bandwidth (BW) Distribution
A30: Bandwidth | B30: Count
A31: 100Mbps | B31: =COUNTIF('Active Orders'!$J$2:$J$499,"100Mbps") -> 4
A32: 25MBPs | B32: =COUNTIF('Active Orders'!$J$2:$J$499,"25MBPs") -> 1
A33: 20MBPs | B33: =COUNTIF('Active Orders'!$J$2:$J$499,"20MBPs") -> 1
A34: 8MBPs | B34: =COUNTIF('Active Orders'!$J$2:$J$499,"8MBPs") -> 10
A35: 6MBPs | B35: =COUNTIF('Active Orders'!$J$2:$J$499,"6MBPs") -> 2
A36: 4MBPs | B36: =COUNTIF('Active Orders'!$J$2:$J$499,"4MBPs") -> 1
A37: Not Specified | B37: =COUNTIFS('Active Orders'!$A$2:$A$499,"<>",'Active Orders'!$J$2:$J$499,"") -> 0
A40: STC vs Mobily Breakdown
A41: Provider | B41: Source Sheet | C41: Count
A42: STC Orders | B42: Active Orders | C42: =COUNTIF('Active Orders'!$B$2:$B$499,"*STC") -> 20
A43: STC Orders | B43: Cancelled Orders | C43: =COUNTIF('Cancelled Orders'!$B$2:$B$500,"*STC") -> 1
A44: Mobily Orders | B44: Active Orders | C44: =COUNTIF('Active Orders'!$B$2:$B$499,"*Mobily") -> 3
A45: Mobily Orders | B45: Cancelled Orders | C45: =COUNTIF('Cancelled Orders'!$B$2:$B$500,"*Mobily") -> 0
A46: Total STC Orders | C46: =SUM(C42:C43) -> 21
A47: Total Mobily Orders | C47: =SUM(C44:C45) -> 3
A49: Active vs Cancelled
A50: Status | B50: Count
A51: Active Orders | B51: =COUNTA('Active Orders'!$B$2:$B$499) -> 23
...
